Workbook
Name Referred: LOOKUPS!$C$2:$C$9
Name Report_Requested: LOOKUPS!$D$2:$D$8
Name Wtg_Att_Mgr_Dec: LOOKUPS!$E$2:$E$12
Name Wtg_Referral_Dec: LOOKUPS!$F$2:$F$13

Sheet MASTER
A1: Row Status | B1: Period | C1: Incident Number | D1: Incident Date | E1: Headcode | F1: Train | G1: Incident Location | H1: TARA Primary Delay Minutes | I1: TARA Canx | J1: Primary Mins Sum | K1: Total Mins | L1: Sum Canx | M1: Equipment Bugle | N1: Vehicle No. | O1: Unit No. | P1: Coupled Unit No. | Q1: 5-9 Car | R1: Train Type | S1: Train Accepted | T1: LNER Investigation Notes | U1: Hitachi Investigation Notes / SAP info / Root Cause | V1: LNER Status Notes | W1: Bugle Mgr | X1: Trust Mgr | Y1: Inc Cause | Z1: Root Cause | AA1: Bugle Dispute Status | AB1: Bugle Status | AC1: LNER Fleet Status | AD1: Report Requested From/Delay Attributed To: | AE1: Master Incident Number | AF1: Date Report Requested/Referred or Delay Closed Out | AG1: Hitachi Status | AH1: Tech | AI1: TIN | AJ1: KPI Code | AK1: Cause Code | AL1: System | AM1: Subsystem | AN1: Failure | AO1: Engineering Comments | AP1: EFC (if Required) In Progress? | AQ1: PHRD? | AR1: PHRD Number | AS1: PIP/MOD Recommended?
A2: New | B2: 2612 | C2: 192749 | D2: 46065 | E2: 1E15 | F2: 09:52 ABERDEEN to KINGS X | G2: EDB MNK | H2: 17 | I2: 0 | J2: 17 | K2: 83 | L2: 0 | M2: 800106 | N2: 811106 | O2: 800106 | Q2: 9 | R2: 80x | S2: 43550 | T2: 1E15 POWER FAULT EDB MNK LVL2 Driver NED 52 contacted LNER STSM to advise that they had come to a stand between Portobello Jn and Musselburgh with a check pan alarm. They advised that they came to a stand and lowered their pantograph in order to complete their checks. They advised that all is okay and have spoken to Hitachi and confirmed that they are ok to continue forward at linespeed using their pantograph. TMS 6602 No Current Draw from OHL LOG 260212-79 refers. SAP 8347717 refers. | U2: Under investigation. | V2: 161321 is the exact same. Both to be disputed with HRL until suitable explanation can be obtained. Disputed with HRL. JC 13/02 | W2: MHB1 | X2: MHB1 | Y2: M1 | AA2: D | AB2: New | AC2: Refer to Level 2 | AE2: 260212-192749 | AG2: Investigation | AI2: =IF(AD2="Availability", 0, IF(AND(AE2="Y", OR(J2>2, L2>0)), 1, 0)) -> 0 | AJ2: 701D | AL2: =IFERROR(IF(AK2="", "", _xlfn.XLOOKUP(AK2, CODES!A:A,CODES!E:E)), "") | AM2: =IFERROR(IF(AK2="", "", _xlfn.XLOOKUP(AK2, CODES!A:A,CODES!G:G)), "") | AN2: =IFERROR(IF(AK2="", "", _xlfn.XLOOKUP(AK2, CODES!A:A,CODES!I:I)), "")
A3: New | B3: 2612 | C3: 192000 | D3: 46065 | E3: 5S08 | F3: 06:34 FERMEPARK to KINGS X | G3: FRMPKRS | H3: 5 | I3: 0 | J3: 5 | K3: 5 | L3: 0 | M3: Undefined | O3: 801208 | Q3: 9 | R3: 80x | T3: 5S08 DEPOT OPS FRMPKRS THE DEPOT REPORT THAT 5S08 WAS HELD AT K451 WAITING FOR THE SIGNAL TO DEPART. | U3: HRE Reject, MTIN – No. Depot report Unit held at K451 waiting for the signal to depart. Class 5 only delay. | V3: TMV/dispute raised. JC 13/02 | W3: MHBJ | X3: MHBJ | Y3: MU | AA3: A | AB3: New | AC3: Investigation | AE3: 260212-192000 | AG3: Rejected - Class 3/5 | AH3: N | AI3: =IF(AD3="Availability", 0, IF(AND(AE3="Y", OR(J3>2, L3>0)), 1, 0)) -> 0 | AJ3: 701A | AK3: 1DB | AL3: =IFERROR(IF(AK3="", "", _xlfn.XLOOKUP(AK3, CODES!A:A,CODES!E:E)), "") -> Operational | AM3: =IFERROR(IF(AK3="", "", _xlfn.XLOOKUP(AK3, CODES!A:A,CODES!G:G)), "") -> NR | AN3: =IFERROR(IF(AK3="", "", _xlfn.XLOOKUP(AK3, CODES!A:A,CODES!I:I)), "") -> Regulation | AO3: Unit late off depot.
A4: New | B4: 2612 | C4: 191778 | D4: 46065 | E4: 5A02 | G4: XNL | J4: 59 | K4: 143 | L4: 0 | M4: NL12 | N4: 82212 | O4: NL12 | Q4: 11 | R4: 225 | T4: 5A02 ABOVE SBAR XNL…..No bogie brake readings | U4: Quirk of the DVT brake system…..Spare set launched | W4: MHBC | X4: MHBC | Y4: MN | AA4: D | AB4: New | AC4: Investigation | AE4: 260212-191778 | AI4: =IF(AD4="Availability", 0, IF(AND(AE4="Y", OR(J4>2, L4>0)), 1, 0)) -> 0 | AJ4: 701D | AL4: =IFERROR(IF(AK4="", "", _xlfn.XLOOKUP(AK4, CODES!A:A,CODES!E:E)), "") | AM4: =IFERROR(IF(AK4="", "", _xlfn.XLOOKUP(AK4, CODES!A:A,CODES!G:G)), "") | AN4: =IFERROR(IF(AK4="", "", _xlfn.XLOOKUP(AK4, CODES!A:A,CODES!I:I)), "")
A5: New | B5: 2612 | C5: 191716 | D5: 46065 | E5: 3Y03 | F5: 04:35 DONCARIEP to YORK Running as 04:57 DONCASTER to YORK | G5: DON | H5: 10 | I5: 0 | J5: 10 | K5: 21 | L5: 0 | M5: 800202 | O5: 800202 | Q5: 5 | R5: 80x | S5: 43819 | T5: 3Y03 UNIT FLT DON ADVISED BY NETWORK RAIL THAT 3Y03 $04:57 DONCASTER - YORK| IS CURRENTLY BEING DELAYED AT DONCASTER DU ETO REPORTS OF HAVING TROUBLE BUILDING AIR. 1Y01 CURRENTLY BEING HELD OUTSIDE OF THE STATION WAITING FOR A PLATFORM. | U5: HRE Reject, MTIN – No, Unit outstabled at Doncaster due to mainline disruption 11/02. Low main res air pressure and associated issues, cleared with an aux off/on of the Unit after air pressure had built up on the Unit. Class 3 only delay. | V5: Drvier report requested - JM. JC 13/02 | W5: MHB1 | X5: MHB1 | Y5: M8 | AA5: A | AB5: New | AC5: Investigation | AE5: 260212-191716 | AG5: Rejected | AH5: N | AI5: =IF(AD5="Availability", 0, IF(AND(AE5="Y", OR(J5>2, L5>0)), 1, 0)) -> 0 | AJ5: 701D | AL5: =IFERROR(IF(AK5="", "", _xlfn.XLOOKUP(AK5, CODES!A:A,CODES!E:E)), "") | AM5: =IFERROR(IF(AK5="", "", _xlfn.XLOOKUP(AK5, CODES!A:A,CODES!G:G)), "") | AN5: =IFERROR(IF(AK5="", "", _xlfn.XLOOKUP(AK5, CODES!A:A,CODES!I:I)), "")
A6: Root Cause, Bugle Dispute Status | B6: 2612 | C6: 190994 | D6: 46064 | E6: 1D26 | F6: 18:03 KINGS X to SKIPTON | G6: DON | H6: 11 | I6: 0 | J6: 11 | K6: 34 | L6: 0 | M6: 800/801 | O6: 800203 | P6: 801106 | Q6: 5 | R6: 80x | S6: 43728 | T6: 1D26 11 OVERTIME DON 19:55 driver reports dispatch staff report smoke from the underframe at Doncaster Station. MC asked if the GU's are pre heating. Driver reports they were. Advised that a relief driver is going to inspect the area reported. Informed driver that smoke is likely due to GU preheating. Relief driver confirmed no evidence of smoke or fire present. Happy for the unit to proceed forward, driver is going to have a check again at LDS and report back. LOG 260211-68 refers. *Safety of the line* | U6: Under investigation. | W6: MHB2 | X6: MHB2 | Y6: M9 | Z6: M9 | AA6: A | AB6: Accepted | AC6: Investigation | AE6: 260211-190994 | AG6: Investigation | AI6: =IF(AD6="Availability", 0, IF(AND(AE6="Y", OR(J6>2, L6>0)), 1, 0)) -> 0 | AJ6: 701D | AL6: =IFERROR(IF(AK6="", "", _xlfn.XLOOKUP(AK6, CODES!A:A,CODES!E:E)), "") | AM6: =IFERROR(IF(AK6="", "", _xlfn.XLOOKUP(AK6, CODES!A:A,CODES!G:G)), "") | AN6: =IFERROR(IF(AK6="", "", _xlfn.XLOOKUP(AK6, CODES!A:A,CODES!I:I)), "")
A7: Root Cause | B7: 2612 | C7: 189004 | D7: 46064 | E7: 5Y26 | F7: 22:26 KINGS X to BOUNDGNCS | G7: BNDSGRN | H7: 33 | I7: 0 | J7: 33 | K7: 33 | L7: 0 | M7: 801225 | O7: 801225 | Q7: 9 | R7: 80x | S7: 43868 | T7: 5Y26 WTG ACCEP BNDSGRN 5Y26 SHOULD BEPART FMP AT 22:40 TMV REPLY SHOWS DEPARTING 22:55 NO INFOAMTION IN TAS. MORE INFOMATION REQUIED FROM BN/FMP DEPOT. | U7: HRE Reject, MTIN – No. Depot report congestion. Class 5 only delay. | W7: MHBJ | X7: MHBJ | Y7: MU | Z7: MU | AA7: A | AB7: Accepted | AC7: Accepted | AE7: 260211-189004 | AG7: Rejected - Class 3/5 | AH7: N | AI7: =IF(AD7="Availability", 0, IF(AND(AE7="Y", OR(J7>2, L7>0)), 1, 0)) -> 0 | AJ7: 701A | AK7: 1BD | AL7: =IFERROR(IF(AK7="", "", _xlfn.XLOOKUP(AK7, CODES!A:A,CODES!E:E)), "") -> Operational | AM7: =IFERROR(IF(AK7="", "", _xlfn.XLOOKUP(AK7, CODES!A:A,CODES!G:G)), "") -> Depot | AN7: =IFERROR(IF(AK7="", "", _xlfn.XLOOKUP(AK7, CODES!A:A,CODES!I:I)), "") -> Process | AO7: Awaiting acceptance onto depot.
A8: Root Cause, Bugle Dispute Status | B8: 2612 | C8: 188162 | D8: 46063 | E8: 1S19 | F8: 14:03 KINGS X to ABERDEEN | G8: DAR | H8: 7 | I8: 0 | J8: 7 | K8: 7 | L8: 0 | M8: 800110 | N8: 816110 | O8: 800110 | Q8: 9 | R8: 80x | S8: 43584 | T8: 1S19 7 OVERTIME DAR Train at a stand at Darlington due to TM unaware that the AIVR was attached underneath 800110. Brief's have gone out and on the update today. LOG 260210-68 refers. | U8: HRE Reject, MTIN – No. Station overtime at Darlington after the Signaller reported to the Driver that there was a strange light underneath the train having been reported by a TPE service. On inspection is was confirmed to be NR AIVR monitoring equipment fitted to the train. | V8: Dispute raised. JC 11/02 Able to dispute. JC 11/02 | W8: MHB1 | X8: MHB1 | Y8: M9 | AA8: D | AB8: New | AC8: Wtg_Att_Mgr_Dec | AE8: 260210-188162 | AG8: Rejected | AH8: N | AI8: =IF(AD8="Availability", 0, IF(AND(AE8="Y", OR(J8>2, L8>0)), 1, 0)) -> 0 | AJ8: 701D | AK8: 1DE | AL8: =IFERROR(IF(AK8="", "", _xlfn.XLOOKUP(AK8, CODES!A:A,CODES!E:E)), "") -> Operational | AM8: =IFERROR(IF(AK8="", "", _xlfn.XLOOKUP(AK8, CODES!A:A,CODES!G:G)), "") -> NR | AN8: =IFERROR(IF(AK8="", "", _xlfn.XLOOKUP(AK8, CODES!A:A,CODES!I:I)), "") -> Other | AO8: TM unaware of AIVR equipment being installed on the train.
A9: Root Cause | B9: 2612 | C9: 187971 | D9: 46063 | E9: 1D20 | F9: 15:10 London Kings Cross - Leeds | G9: PBO | J9: 3 | K9: 11 | L9: 0 | M9: NL12 | N9: 12404 | O9: NL12 | Q9: 11 | R9: 225 | T9: 1D20 3 OVERTIME PBO | U9: Rough riding and knocking noise from underframe | V9: WO 5089017 Centre casting shim disintegrated, same renewed & No's 2 & 3 yaw dampers renewed | W9: MHBB | X9: MHBB | Y9: M9 | AA9: A | AB9: New | AC9: Accepted | AE9: 260210-187971 | AH9: Y | AI9: =IF(AD9="Availability", 0, IF(AND(AE9="Y", OR(J9>2, L9>0)), 1, 0)) -> 0 | AJ9: 701D | AL9: =IFERROR(IF(AK9="", "", _xlfn.XLOOKUP(AK9, CODES!A:A,CODES!E:E)), "") | AM9: =IFERROR(IF(AK9="", "", _xlfn.XLOOKUP(AK9, CODES!A:A,CODES!G:G)), "") | AN9: =IFERROR(IF(AK9="", "", _xlfn.XLOOKUP(AK9, CODES!A:A,CODES!I:I)), "")
A10: Reassigned to Fleet, Bugle Mgr, Trust Mgr, Inc Cause, Root Cause, Bugle Dispute Status | B10: 2612 | C10: 187126 | D10: 46063 | E10: 3A12 | F10: 07:15 DONCARIEP to LEEDS | G10: LDS | H10: 0 | I10: 1 | J10: 0 | K10: 2 | L10: 1 | M10: 800111 | O10: 801201 | Q10: 9 | R10: 80x | S10: 44077 | T10: 3A12 CANCELLED DONCIEP 3A12 EXISTS BUT STARTED AT NEVILLE HILL VICE DON IEP. | U10: HRE Reject, MTIN – No. 3A12 formed from Unit 801021 departing from Neville Hill vice DON IEP due to the ongoing investigation into a TMS Brake discrepancy fault on Unit 800111 reported 09/02. 3A12 canx DON IEP - LDS. Class 3 only delay. | W10: MHB1 | X10: MHB1 | Y10: MS | Z10: MS | AA10: A | AB10: Accepted | AC10: Accepted | AE10: 260210-187126 | AG10: Rejected - Class 3/5 | AH10: N | AI10: =IF(AD10="Availability", 0, IF(AND(AE10="Y", OR(J10>2, L10>0)), 1, 0)) -> 0 | AJ10: 701A | AK10: 1CC | AL10: =IFERROR(IF(AK10="", "", _xlfn.XLOOKUP(AK10, CODES!A:A,CODES!E:E)), "") -> Operational | AM10: =IFERROR(IF(AK10="", "", _xlfn.XLOOKUP(AK10, CODES!A:A,CODES!G:G)), "") -> Control | AN10: =IFERROR(IF(AK10="", "", _xlfn.XLOOKUP(AK10, CODES!A:A,CODES!I:I)), "") -> HRL CPC | AO10: Unit started XNL vice Doncaster IEP.
A11: Root Cause | B11: 2612 | C11: 186855 | D11: 46063 | E11: 1A05 | F11: 06:05 Leeds - London Kings Cross | G11: NNG | J11: 4 | K11: 32 | L11: 0 | M11: NL16 | N11: 91111 | O11: NL16 | Q11: 11 | R11: 225 | T11: 1A05 4 OVERTIME NNG | U11: Set will not go above 110mph | V11: WO 5089002 E70 microswitch corrected | W11: MHBA | X11: MHBA | Y11: MB | AA11: A | AB11: New | AC11: Accepted | AE11: 260210-186855 | AH11: N | AI11: =IF(AD11="Availability", 0, IF(AND(AE11="Y", OR(J11>2, L11>0)), 1, 0)) -> 0 | AJ11: 701D | AL11: =IFERROR(IF(AK11="", "", _xlfn.XLOOKUP(AK11, CODES!A:A,CODES!E:E)), "") | AM11: =IFERROR(IF(AK11="", "", _xlfn.XLOOKUP(AK11, CODES!A:A,CODES!G:G)), "") | AN11: =IFERROR(IF(AK11="", "", _xlfn.XLOOKUP(AK11, CODES!A:A,CODES!I:I)), "")
A12: Root Cause | B12: 2612 | C12: 185801 | D12: 46062 | E12: 1E17 | F12: 13:30 EDINBURGH to KINGS X | G12: DON DONCLCJ | H12: 2 | I12: 0 | J12: 2 | K12: 8 | L12: 0 | M12: 801229 | N12: 825229 | O12: 801229 | Q12: 9 | R12: 80x | S12: 43972 | T12: 1E17 2 LOST DON DONCLCJ TRACTION CONVERTOR ISOLATED IN 825229 / SET 801229 COACH H. SAP 8326757 refers. RES 92764 refers - open for 13 days. | U12: MTIN NO, HRE REJECT - Sub threshold delay. | W12: MHB2 | X12: MHB2 | Y12: MD | AA12: D | AB12: New | AC12: Accepted | AE12: 260209-185801 | AG12: Rejected - Sub Threshold | AH12: N | AI12: =IF(AD12="Availability", 0, IF(AND(AE12="Y", OR(J12>2, L12>0)), 1, 0)) -> 0 | AJ12: 701D | AK12: PH6 | AL12: =IFERROR(IF(AK12="", "", _xlfn.XLOOKUP(AK12, CODES!A:A,CODES!E:E)), "") -> Traction and Power Equipment | AM12: =IFERROR(IF(AK12="", "", _xlfn.XLOOKUP(AK12, CODES!A:A,CODES!G:G)), "") -> Traction Converter | AN12: =IFERROR(IF(AK12="", "", _xlfn.XLOOKUP(AK12, CODES!A:A,CODES!I:I)), "") -> Fault not Investigated | AO12: Sub-threshold delay, Traction Converter isolated.
A13: Root Cause | B13: 2612 | C13: 185246 | D13: 46062 | E13: 1E16 | F13: 13:00 EDINBURGH to KINGS X | G13: NCL | H13: 14 | I13: 0 | J13: 14 | K13: 21 | L13: 0 | M13: 801202 | N13: 826202 | O13: 801202 | Q13: 9 | R13: 80x | S13: 43988 | T13: 1E16 14 OVERTIME NCL Smoke detection activation. CCTV suggests person in toilet was possibly vaping. LOG 260209-45 refers. SAP 8342594 refers. | U13: MTIN NO, HRE REJECT - CCTV review confirms a passenger entering the toilet at the time of the alert and thought to have been smoking/vaping in the toilet. HFMT historical events have been monitored since and no further TMS0305 events have occurred. | V13: request to be referred to passenger vandalism code. JC 10/02 Crew reports requested due to time taken to reset. JC 11/02 Reports received, details requested from HRL. JC 11/02 14:20 - 14:38 Details passed onto JP. JC 13/02 | W13: MHB2 | X13: MHB2 | Y13: MT | AA13: D | AB13: New | AC13: Wtg_Att_Mgr_Dec | AE13: 260209-185246 | AG13: Rejected | AH13: N | AI13: =IF(AD13="Availability", 0, IF(AND(AE13="Y", OR(J13>2, L13>0)), 1, 0)) -> 0 | AJ13: 701D | AK13: 2BN | AL13: =IFERROR(IF(AK13="", "", _xlfn.XLOOKUP(AK13, CODES!A:A,CODES!E:E)), "") -> LNER | AM13: =IFERROR(IF(AK13="", "", _xlfn.XLOOKUP(AK13, CODES!A:A,CODES!G:G)), "") -> Other | AN13: =IFERROR(IF(AK13="", "", _xlfn.XLOOKUP(AK13, CODES!A:A,CODES!I:I)), "") -> Passenger Vandalism | AO13: Passenger thought to have been vaping in toilet at time of smoke alarm.
A14: Root Cause | B14: 2612 | C14: 185048 | D14: 46062 | E14: 1B86 | F14: 12:47 KINGS X to LINCLNCEN | G14: KGX | H14: 15 | I14: 0 | J14: 15 | K14: 31 | L14: 0 | M14: 800206 | O14: 800206 | Q14: 5 | R14: 80x | S14: 43721 | T14: 1B86 15 LATE START KGX Low Air at departure, possible set up issue when swapping pans around. LOG 260209-43 refers. SAP 8342602 refers. | U14: MTIN NO, HRE REJECT - Driver error. | V14: referral request sent to HM. JC 10/02 | W14: MHB1 | X14: MHB1 | Y14: MD | AA14: D | AB14: New | AC14: Wtg_Att_Mgr_Dec | AE14: 260209-185048 | AG14: Rejected | AH14: N | AI14: =IF(AD14="Availability", 0, IF(AND(AE14="Y", OR(J14>2, L14>0)), 1, 0)) -> 0 | AJ14: 701D | AK14: 1AA | AL14: =IFERROR(IF(AK14="", "", _xlfn.XLOOKUP(AK14, CODES!A:A,CODES!E:E)), "") -> Operational | AM14: =IFERROR(IF(AK14="", "", _xlfn.XLOOKUP(AK14, CODES!A:A,CODES!G:G)), "") -> Staff | AN14: =IFERROR(IF(AK14="", "", _xlfn.XLOOKUP(AK14, CODES!A:A,CODES!I:I)), "") -> Driver | AO14: Driver did not carry out power configuration correctly.
A15: Root Cause | B15: 2612 | C15: 184308 | D15: 46062 | E15: 1A07 | F15: 06:30 BRADFORSQ to KINGS X | G15: LDS | H15: 4 | I15: 0 | J15: 4 | K15: 4 | L15: 0 | M15: 801204 | N15: 821204 | O15: 801204 | Q15: 9 | R15: 80x | S15: 44005 | T15: 1A07 4 OVERTIME LDS Driver working 1A07 reports that a TRI has advised that the 821 pan has a very thin carbon and locked it out, driver has been advised to use the alternative pan. LOG 260209-35 refers. SAP 8327670 refers. | U15: Under Investigation. | W15: MHB2 | X15: MHB2 | Y15: M1 | AA15: A | AB15: New | AC15: Investigation | AE15: 260209-184308 | AG15: Investigation | AI15: =IF(AD15="Availability", 0, IF(AND(AE15="Y", OR(J15>2, L15>0)), 1, 0)) -> 0 | AJ15: 701D | AL15: =IFERROR(IF(AK15="", "", _xlfn.XLOOKUP(AK15, CODES!A:A,CODES!E:E)), "") | AM15: =IFERROR(IF(AK15="", "", _xlfn.XLOOKUP(AK15, CODES!A:A,CODES!G:G)), "") | AN15: =IFERROR(IF(AK15="", "", _xlfn.XLOOKUP(AK15, CODES!A:A,CODES!I:I)), "")
A16: Root Cause | B16: 2612 | C16: 184293 | D16: 46062 | E16: 3A11 | F16: 06:40 NEVHILL D to BRADFORSQ | G16: XNL | H16: 7 | I16: 0 | J16: 7 | K16: 7 | L16: 0 | M16: 801101/03 | O16: 801101 | P16: 801103 | Q16: 5 | R16: 80x | S16: 43700 | T16: 3A11 7 LATE START XNL Awaiting depot report. | U16: HRE Reject, MTIN – No. Depot report Unit held waiting for the signal to depart. Class 3 only delay. | V16: TMV check required. | W16: MHBM | X16: MHBM | Y16: MU | AA16: A | AB16: New | AC16: Wtg_Att_Mgr_Dec | AE16: 260209-184293 | AG16: Rejected - Class 3/5 | AH16: N | AI16: =IF(AD16="Availability", 0, IF(AND(AE16="Y", OR(J16>2, L16>0)), 1, 0)) -> 0 | AJ16: 701A | AK16: 1BD | AL16: =IFERROR(IF(AK16="", "", _xlfn.XLOOKUP(AK16, CODES!A:A,CODES!E:E)), "") -> Operational | AM16: =IFERROR(IF(AK16="", "", _xlfn.XLOOKUP(AK16, CODES!A:A,CODES!G:G)), "") -> Depot | AN16: =IFERROR(IF(AK16="", "", _xlfn.XLOOKUP(AK16, CODES!A:A,CODES!I:I)), "") -> Process
A17: Root Cause | B17: 2612 | C17: 184268 | D17: 46062 | E17: 1Y04 | F17: 05:27 NCASTLCEN to KINGS X | G17: SHFTHLJ TEMPLHJ | H17: 11 | I17: 0 | J17: 11 | K17: 11 | L17: 0 | M17: 801201 | O17: 801201 | Q17: 9 | R17: 80x | S17: 44077 | T17: 1Y04 11 LOST SHFTHLJ TEMPLH CCIL reports that the driver of 1Y04 reported a loud bang underneath the train on the approach to Heck Ground Frame. *Safety of the line, FFCCTV requested for review* LOG 260209-34 refers. | U17: HRE Reject, MTIN – No. DVR of 1Y04 reports a loud bang underneath the train on the approach to Heck Ground Frame. Delays incurred by 1S02 & 1A90 examining the UM & DM lines with nothing found. | W17: MHB2 | X17: MHB2 | Y17: M9 | AA17: D | AB17: New | AC17: Wtg_Att_Mgr_Dec | AE17: 260209-184268 | AG17: Rejected | AH17: N | AI17: =IF(AD17="Availability", 0, IF(AND(AE17="Y", OR(J17>2, L17>0)), 1, 0)) -> 0 | AJ17: 701D | AK17: CFA | AL17: =IFERROR(IF(AK17="", "", _xlfn.XLOOKUP(AK17, CODES!A:A,CODES!E:E)), "") -> Bodyshell and Exterior | AM17: =IFERROR(IF(AK17="", "", _xlfn.XLOOKUP(AK17, CODES!A:A,CODES!G:G)), "") -> Structure | AN17: =IFERROR(IF(AK17="", "", _xlfn.XLOOKUP(AK17, CODES!A:A,CODES!I:I)), "") -> Underframe | AO17: Safety of the line report.
A18: Root Cause | B18: 2612 | C18: 184254 | D18: 46062 | E18: 1N01 | F18: 06:33 KINGS X to NCASTLCEN | G18: KGX | H18: 11 | I18: 0 | J18: 11 | K18: 11 | L18: 0 | M18: 801214 | N18: 821214 | O18: 801214 | Q18: 9 | R18: 80x | S18: 43943 | T18: 1N01 11 LATE START KGX DSD Pedal unable to cancel LOG 260209-32 refers. SAP 8342124 refers. | U18: MTIN YES, HRE ACCEPT - Budget Lock lid left open in error after planned maintenance, M/H error. | W18: MHB2 | X18: MHB2 | Y18: M8 | AA18: A | AB18: New | AC18: Accepted | AE18: 260209-184254 | AG18: Accepted | AH18: Y | AI18: =IF(AD18="Availability", 0, IF(AND(AE18="Y", OR(J18>2, L18>0)), 1, 0)) -> 0 | AJ18: 701D | AK18: SD7 | AL18: =IFERROR(IF(AK18="", "", _xlfn.XLOOKUP(AK18, CODES!A:A,CODES!E:E)), "") -> Safety System | AM18: =IFERROR(IF(AK18="", "", _xlfn.XLOOKUP(AK18, CODES!A:A,CODES!G:G)), "") -> DSD | AN18: =IFERROR(IF(AK18="", "", _xlfn.XLOOKUP(AK18, CODES!A:A,CODES!I:I)), "") -> Non Technical | AO18: Budget Lock lid on DSD pedal left open in error after planned maintenance, M/H error.
A19: Root Cause | B19: 2612 | C19: 184173 | D19: 46062 | E19: 1A02 | F19: 05:00 Leeds - London Kings Cross | G19: LDS | J19: 0 | K19: 16 | L19: 2 | M19: NL12 | N19: 82212 | O19: NL12 | Q19: 11 | R19: 225 | T19: 1A02 CANCELLED LDS…..No bogie brake readings | U19: Quirk of the DVT brake system | V19: WO 5088976 | W19: MHBC | X19: MHBC | Y19: MN | AA19: A | AB19: New | AC19: Wtg_Att_Mgr_Dec | AE19: 260209-184173 | AI19: =IF(AD19="Availability", 0, IF(AND(AE19="Y", OR(J19>2, L19>0)), 1, 0)) -> 0 | AJ19: 701D | AL19: =IFERROR(IF(AK19="", "", _xlfn.XLOOKUP(AK19, CODES!A:A,CODES!E:E)), "") | AM19: =IFERROR(IF(AK19="", "", _xlfn.XLOOKUP(AK19, CODES!A:A,CODES!G:G)), "") | AN19: =IFERROR(IF(AK19="", "", _xlfn.XLOOKUP(AK19, CODES!A:A,CODES!I:I)), "")
A20: Root Cause | B20: 2612 | C20: 183386 | D20: 46061 | E20: 1A27 | F20: 15:34 Bradford Foster Square - London Kings Cross | G20: WKF | J20: 2 | K20: 3 | L20: 0 | M20: NL08 | N20: 91109 | O20: NL08 | Q20: 11 | R20: 225 | T20: 1A27 2 LOST WHITEHLJN WKF…..Adhesion | U20: Adhesion | V20: Adhesion | W20: MHBA | X20: MHBA | Y20: MP | AA20: A | AB20: New | AC20: Accepted | AE20: 260208-183386 | AH20: N | AI20: =IF(AD20="Availability", 0, IF(AND(AE20="Y", OR(J20>2, L20>0)), 1, 0)) -> 0 | AJ20: 750 | AL20: =IFERROR(IF(AK20="", "", _xlfn.XLOOKUP(AK20, CODES!A:A,CODES!E:E)), "") | AM20: =IFERROR(IF(AK20="", "", _xlfn.XLOOKUP(AK20, CODES!A:A,CODES!G:G)), "") | AN20: =IFERROR(IF(AK20="", "", _xlfn.XLOOKUP(AK20, CODES!A:A,CODES!I:I)), "")
A21: Removed - Reassigned | B21: 2612 | C21: 183270 | D21: 46061 | E21: 5E22 | F21: 15:08 CRAIGNTNY to EDINBURGH | G21: XCN | H21: 24 | I21: 0 | J21: 24 | K21: 43 | L21: 0 | M21: 801226 | O21: 801226 | Q21: 9 | R21: 80x | S21: 43908 | T21: 5E22 24 LATE START XCN SET SWAP BETWEEN 1S12 TO FROM 1E20 & 1S09 TO FORM 1E21. REASON FOR SWAP WAS 801226 FITNESS TO RUN RAN OUT AT 22:26 SO HASD TO SWAP ONTO DIAGRAM SO COULD GET BACK BEFORE IT RAN OUT. SET SWAP SENT TO BOX 12:40 THEY SAID THEY CAN DO SWAP BUT 5E22 WOULD GET DELAY.AS COULD PUT INTO DIFFRENT PLATFORMS. TMV SHOWED AFTER 1E20 15:00 EDB-YRK DEPARTED PLATFORM 2 WAS AVAILABLE SO 5E22 SHOULD OFF LEFT CT AT 15:08AND DID NOT LEAVE UNTIL 15:25 & WENT INTO BOOKED PLATFORM 6. | U21: HRE Reject, MTIN – No. Depot report Unit held by the signaller awaiting platform space at Edinburgh Waverley. | V21: Details passed onto JP. JC 09/02 Comments required from FPPMs. JC 09/02 | W21: THBN | X21: THBN | Y21: TB | AA21: A | AB21: New | AC21: Investigation | AE21: 260208-183270 | AI21: =IF(AD21="Availability", 0, IF(AND(AE21="Y", OR(J21>2, L21>0)), 1, 0)) -> 0 | AJ21: 701B | AL21: =IFERROR(IF(AK21="", "", _xlfn.XLOOKUP(AK21, CODES!A:A,CODES!E:E)), "") | AM21: =IFERROR(IF(AK21="", "", _xlfn.XLOOKUP(AK21, CODES!A:A,CODES!G:G)), "") | AN21: =IFERROR(IF(AK21="", "", _xlfn.XLOOKUP(AK21, CODES!A:A,CODES!I:I)), "")
A22: Removed - Reassigned | B22: 2612 | C22: 182765 | D22: 46061 | E22: 1E07 | F22: 08:55 EDINBURGH to KINGS X Running as 08:55 EDINBURGH to YORK | G22: EDB | H22: 11 | I22: 0 | J22: 14 | K22: 30 | L22: 0 | M22: 801226 | O22: 801226 | Q22: 9 | R22: 80x | S22: 43908 | T22: 1E07 11 LATE START EDB SET WAS STABLED OVERNIGHT BUT IN THE MORNING HAD SIGNIFICANT ISSUE FIRST BUILDING UP AIR AND LATER THE PANTOGRAPH WAS UP BUT IT SHOWED BRAKE CONTROL FAULT WHICH DELAYED SERVICE IN DEPART EDB. LOG 260208-64 refers. | U22: HRE Reject, MTIN – No. Unit outstabled at EDB overnight in reaction to disruption 06/02. Low main res start up issues reported by the DVR. GU started to build air, Unit then auxed off to clear associated BCU faults one main res air pressure was established. | V22: Suspect low air start up issues. Drivers report requested - DR. JC 09/02 Details sent to JP, ops or driver issue. JC 09/02 Driver late to arrive, 08:37. JP moving to OPS standards. 10.02 S.B | W22: THBQ | X22: THBQ | Y22: TY | AA22: A | AB22: New | AC22: Referred | AE22: 260208-182765 | AG22: Rejected | AH22: N | AI22: =IF(AD22="Availability", 0, IF(AND(AE22="Y", OR(J22>2, L22>0)), 1, 0)) -> 0 | AJ22: 701B | AK22: 1AA | AL22: =IFERROR(IF(AK22="", "", _xlfn.XLOOKUP(AK22, CODES!A:A,CODES!E:E)), "") -> Operational | AM22: =IFERROR(IF(AK22="", "", _xlfn.XLOOKUP(AK22, CODES!A:A,CODES!G:G)), "") -> Staff | AN22: =IFERROR(IF(AK22="", "", _xlfn.XLOOKUP(AK22, CODES!A:A,CODES!I:I)), "") -> Driver | AO22: Unit outstabled over night at EDB. Low air start up issues.
A23: Removed - Reassigned | B23: 2612 | C23: 181742 | D23: 46060 | E23: 1S15 | F23: 12:03 KINGS X to INVERNES Running as 12:51 PETERBORO to INVERNES | G23: EDB | H23: 7 | I23: 0 | J23: 7 | K23: 14 | L23: 0 | M23: 801206 | O23: 801206 | Q23: 9 | R23: 80x | S23: 44013 | T23: 1S15 SET SWAP EDB 1S15 801206 SO REQUIRED A SET SWAP AT EDB WITH 5E25. 1S15 WILL FORM 1E25 EDB-PBO, 5E25 FORMED 1S15 EDB-INV. PLEASE MERGE WITH TIN 179043 DUE TO SET IMBALANCE DUE TO DEWIREMENT AT HAMBLETON 06.02.26. Swapped with 800106. LOG 260206-64 refers. | U23: HRE Reject, MTIN – No. 1S15 formed by 9ce vice 9cbi KGX - EDB in reaction to disruption 06/02/26 due to OHL damage. Unit 800106 swapped to form 1S15 EDB - ABD incurring a 7-minute delay. | V23: Merge requested. Jc 09/02 ADD event/ De-wirment 179043 | W23: THBN | X23: THBN | Y23: TB | AA23: A | AB23: New | AC23: Wtg_Att_Mgr_Dec | AE23: 260207-181742 | AG23: Rejected | AH23: N | AI23: =IF(AD23="Availability", 0, IF(AND(AE23="Y", OR(J23>2, L23>0)), 1, 0)) -> 0 | AJ23: 701B | AK23: 1DE | AL23: =IFERROR(IF(AK23="", "", _xlfn.XLOOKUP(AK23, CODES!A:A,CODES!E:E)), "") -> Operational | AM23: =IFERROR(IF(AK23="", "", _xlfn.XLOOKUP(AK23, CODES!A:A,CODES!G:G)), "") -> NR | AN23: =IFERROR(IF(AK23="", "", _xlfn.XLOOKUP(AK23, CODES!A:A,CODES!I:I)), "") -> Other | AO23: Set swap required at EDB following disruption from ADD event on 06/02.
A24: Root Cause | B24: 2612 | C24: 181387 | D24: 46060 | E24: 1A19 | F24: 11:37 Bradford Forster Square - Peterborough | G24: DON DONCLCJ | J24: 10 | K24: 17 | L24: 0 | M24: NL08 | N24: 91130 | O24: NL08 | Q24: 11 | R24: 225 | T24: 1A19 PANTO/AC DON DONCLCJ…..LOLL | U24: Lost line light | V24: WO 5088956 | W24: MHBA | X24: MHBA | Y24: M1 | AA24: A | AB24: New | AC24: Accepted | AE24: 260207-181387 | AH24: Y | AI24: =IF(AD24="Availability", 0, IF(AND(AE24="Y", OR(J24>2, L24>0)), 1, 0)) -> 0 | AJ24: 701D | AL24: =IFERROR(IF(AK24="", "", _xlfn.XLOOKUP(AK24, CODES!A:A,CODES!E:E)), "") | AM24: =IFERROR(IF(AK24="", "", _xlfn.XLOOKUP(AK24, CODES!A:A,CODES!G:G)), "") | AN24: =IFERROR(IF(AK24="", "", _xlfn.XLOOKUP(AK24, CODES!A:A,CODES!I:I)), "")
A25: Root Cause | B25: 2612 | C25: 180998 | D25: 46060 | E25: 3S08 | F25: 08:55 NEVHILL D to YORK | G25: XNL | H25: 7 | I25: 0 | J25: 7 | K25: 16 | L25: 0 | M25: 801222 | O25: 801222 | Q25: 9 | R25: 80x | S25: 43864 | T25: 3S08 7 LATE START XNL Unit late from depot, awaiting report. | U25: HRE Reject, MTIN – No. Depot report that the Driver did not ring to advise that they were ready to depart until 09:00 (booked departure 08:55). Class 3 only delay. | V25: Drivers report requested - JM. JC 09/02 Depot process delay. JC 13/02 | W25: MHBM | X25: MHBM | Y25: MU | AA25: A | AB25: New | AC25: Accepted | AE25: 260207-180998 | AG25: Rejected - Class 3/5 | AH25: N | AI25: =IF(AD25="Availability", 0, IF(AND(AE25="Y", OR(J25>2, L25>0)), 1, 0)) -> 0 | AJ25: 701A | AK25: 1BD | AL25: =IFERROR(IF(AK25="", "", _xlfn.XLOOKUP(AK25, CODES!A:A,CODES!E:E)), "") -> Operational | AM25: =IFERROR(IF(AK25="", "", _xlfn.XLOOKUP(AK25, CODES!A:A,CODES!G:G)), "") -> Depot | AN25: =IFERROR(IF(AK25="", "", _xlfn.XLOOKUP(AK25, CODES!A:A,CODES!I:I)), "") -> Process | AO25: Unit late off depot.
A26: Check - not on Fleet Attr | B26: 2612 | C26: 180628 | D26: 46060 | G26: XNL | J26: 6 | K26: 6 | L26: 0 | M26: NL08 | O26: NL08 | Q26: 11 | R26: 225 | T26: 5A05 6 LATE START XNL | U26: Following late departure | V26: Following late departure | W26: MHBM | X26: MHBM | Y26: MU | AA26: D | AB26: New | AC26: Investigation | AE26: 260207-180628 | AH26: N | AI26: =IF(AD26="Availability", 0, IF(AND(AE26="Y", OR(J26>2, L26>0)), 1, 0)) -> 0 | AJ26: 701A | AL26: =IFERROR(IF(AK26="", "", _xlfn.XLOOKUP(AK26, CODES!A:A,CODES!E:E)), "") | AM26: =IFERROR(IF(AK26="", "", _xlfn.XLOOKUP(AK26, CODES!A:A,CODES!G:G)), "") | AN26: =IFERROR(IF(AK26="", "", _xlfn.XLOOKUP(AK26, CODES!A:A,CODES!I:I)), "")
A27: Removed - Reassigned | B27: 2612 | C27: 179769 | D27: 46059 | E27: 1S19 | F27: 14:03 KINGS X to ABERDEEN | G27: YRK | H27: 4 | I27: 0 | J27: 4 | K27: 4 | L27: 0 | M27: 800105 | N27: 819105 | O27: 800105 | Q27: 9 | R27: 80x | S27: 43572 | T27: 1S19 PANTO YRK Raising pan in platform, suspect unit operating in diesel following ADD event. | U27: HRE Reject, MTIN – No. Quartz report states TM checking whether they were supposed to be issued an SSO for NTR at York (York staff had not been asked to do this) & volume of passengers due to disruption caused by OHL damage. | V27: Drivers report requested - AAB. JC 09/02 TM report requested - HM. JC 09/02 Drvier reports passenger loadings, details sent onto JP. JC 11/02 | W27: THBN | X27: THBN | Y27: TP | AA27: A | AB27: New | AC27: Wtg_Att_Mgr_Dec | AE27: 260206-179769 | AG27: Rejected | AH27: N | AI27: =IF(AD27="Availability", 0, IF(AND(AE27="Y", OR(J27>2, L27>0)), 1, 0)) -> 0 | AJ27: 701B | AK27: 1AB | AL27: =IFERROR(IF(AK27="", "", _xlfn.XLOOKUP(AK27, CODES!A:A,CODES!E:E)), "") -> Operational | AM27: =IFERROR(IF(AK27="", "", _xlfn.XLOOKUP(AK27, CODES!A:A,CODES!G:G)), "") -> Staff | AN27: =IFERROR(IF(AK27="", "", _xlfn.XLOOKUP(AK27, CODES!A:A,CODES!I:I)), "") -> TM | AO27: TM checking whether they were supposed to be issued an SSO for NTR at York
A28: Root Cause, Bugle Dispute Status | B28: 2612 | C28: 179509 | D28: 46059 | E28: 1A30 | F28: 17:40 LEEDS to KINGS X | G28: LEEDS | H28: 0 | I28: 1 | J28: 0 | K28: 0 | L28: 1 | M28: 800111 | N28: 818111 | O28: 800111 | Q28: 9 | R28: 80x | S28: 43532 | T28: 1A30 FITTERS ATTENTION LDS From min braking to max moving the CPBC brake pressure don't rise along with the CPBC until nearly into max and then BCP pressures rise. Driver not happy with the issue and not taking unit due to potential passing a signal if pressure are not rising. TRI in attendance. Possible LAD10 card issue. LOG 260206-78 refers. SAP 8339327 refers - | U28: Under investigation. | V28: Drivers report requested - JM. JC 09/02 | W28: MHB1 | X28: MHB1 | Y28: MN | Z28: MN | AA28: A | AB28: Accepted | AC28: Investigation | AE28: 260206-179509 | AG28: Investigation | AI28: =IF(AD28="Availability", 0, IF(AND(AE28="Y", OR(J28>2, L28>0)), 1, 0)) -> 0 | AJ28: 701D | AL28: =IFERROR(IF(AK28="", "", _xlfn.XLOOKUP(AK28, CODES!A:A,CODES!E:E)), "") | AM28: =IFERROR(IF(AK28="", "", _xlfn.XLOOKUP(AK28, CODES!A:A,CODES!G:G)), "") | AN28: =IFERROR(IF(AK28="", "", _xlfn.XLOOKUP(AK28, CODES!A:A,CODES!I:I)), "")
A29: Root Cause | B29: 2612 | C29: 179324 | D29: 46059 | E29: 1D20 | F29: 15:10 London Kings Cross - Leeds | G29: KNGXBEL | J29: 5 | K29: 5 | L29: 0 | M29: NL06 | O29: NL06 | Q29: 11 | R29: 225 | T29: 1D20 BRAKES KNGXBEL | W29: MHBA | X29: MHBA | Y29: MN | AA29: A | AB29: New | AC29: Investigation | AE29: 260206-179324 | AI29: =IF(AD29="Availability", 0, IF(AND(AE29="Y", OR(J29>2, L29>0)), 1, 0)) -> 0 | AJ29: 701D | AL29: =IFERROR(IF(AK29="", "", _xlfn.XLOOKUP(AK29, CODES!A:A,CODES!E:E)), "") | AM29: =IFERROR(IF(AK29="", "", _xlfn.XLOOKUP(AK29, CODES!A:A,CODES!G:G)), "") | AN29: =IFERROR(IF(AK29="", "", _xlfn.XLOOKUP(AK29, CODES!A:A,CODES!I:I)), "")
A30: Removed | B30: 2612 | C30: 178518 | D30: 46059 | F30: 09:14 CRAIGNTNY to EDINBURGH | G30: XCN | H30: 5 | I30: 0 | J30: 5 | K30: 5 | L30: 0 | M30: 801220 | O30: 801220 | Q30: 9 | R30: 80x | S30: 43852 | T30: 5E10 LATE START XCN TMV REPLAY SHOWS 5Z56 ROUTED INTO XCN DEPOT, PREVENTING RT DEPARTURE OF 5E10. | U30: HRE Reject, MTIN – No. Depot report 5E10 delayed due to 5Z00 arriving from the mainline. Class 5 only delay. | V30: Details passed onto JP. Jc 09/02 Incident has been removed and merged to Scotrail. 10/02 S.B | W30: MHBK | X30: MHBK | Y30: MU | AA30: D | AB30: New | AC30: Referred | AE30: 260206-178518 | AG30: Rejected - Class 3/5 | AH30: N | AI30: =IF(AD30="Availability", 0, IF(AND(AE30="Y", OR(J30>2, L30>0)), 1, 0)) -> 0 | AJ30: 701A | AK30: 1DB | AL30: =IFERROR(IF(AK30="", "", _xlfn.XLOOKUP(AK30, CODES!A:A,CODES!E:E)), "") -> Operational | AM30: =IFERROR(IF(AK30="", "", _xlfn.XLOOKUP(AK30, CODES!A:A,CODES!G:G)), "") -> NR | AN30: =IFERROR(IF(AK30="", "", _xlfn.XLOOKUP(AK30, CODES!A:A,CODES!I:I)), "") -> Regulation | AO30: Unit late off depot.
A31: Root Cause | B31: 2612 | C31: 178432 | D31: 46059 | E31: 1E03 | F31: 06:30 EDINBURGH to KINGS X | G31: NCL KEBGSJN | H31: 2 | I31: 0 | J31: 2 | K31: 2 | L31: 0 | M31: 801223 | N31: 828223 | O31: 801223 | Q31: 9 | R31: 80x | S31: 43896 | T31: 1E03 2 LOST NCL KEBGSJN 1E03 TO DEPART NCL VIA HLB TO PUT SET IN REVERSE, REQUIRED BY HITACHI TO FIX THE TRACTION CONVERTER. SAP 8292796 refers. | U31: Sub threshold delay. CPC request for Unit to be turned at Newcastle and into reverse formation for EOD maintenance requirements at DON IEP (K1 - 801223 Traction Converter reps & RUX001 (DON). | V31: Email sent to JP to change to 701A - MS. Jc 09/02 | W31: MHB2 | X31: MHB2 | Y31: MD | AA31: A | AB31: New | AC31: Accepted | AE31: 260206-178432 | AG31: Rejected - Sub Threshold | AH31: N | AI31: =IF(AD31="Availability", 0, IF(AND(AE31="Y", OR(J31>2, L31>0)), 1, 0)) -> 0 | AJ31: 701D | AK31: 1CC | AL31: =IFERROR(IF(AK31="", "", _xlfn.XLOOKUP(AK31, CODES!A:A,CODES!E:E)), "") -> Operational | AM31: =IFERROR(IF(AK31="", "", _xlfn.XLOOKUP(AK31, CODES!A:A,CODES!G:G)), "") -> Control | AN31: =IFERROR(IF(AK31="", "", _xlfn.XLOOKUP(AK31, CODES!A:A,CODES!I:I)), "") -> HRL CPC | AO31: Unit turned at Newcastle for EoD maintenance requirements.
A32: Root Cause, Bugle Dispute Status | B32: 2612 | C32: 177745 | D32: 46059 | E32: 1E10 | F32: 10:00 EDINBURGH to KINGS X | G32: EDB | H32: 0 | I32: 1 | J32: 0 | K32: 5 | L32: 1 | M32: 801220 | N32: 824220 | O32: 801220 | Q32: 9 | R32: 80x | S32: 43852 | T32: 1E10 CANCELLED EDB HFMC advises that a pest has been seen on the train. HFMC have asked if traps can be put down and advise set in service on 06/02. STSM has asked what kind of traps will be used and clarification to be given regarding this issue. Cannot swap set out as nothing available at Craigentinny. HFMC advise that Rentokil have not answered the message. Waiting to here back from HFMC as they are due to have a meeting shortly with Depot staff on updates of sets. LOG 260206-10 refers. SAP 8334663 refers. | U32: HRE Reject, MTIN – No. Unit 801220 not available for service due to the ongoing investigation into reports of a mouse in vehicle 824220 reported whilst working as 1S25 on the 05/02. In reaction, 1E10 cancelled. Covered under Availability. | W32: MHB2 | X32: MHB2 | Y32: MS | Z32: MS | AA32: A | AB32: Accepted | AC32: Accepted | AE32: 260206-177745 | AG32: Availability | AH32: N | AI32: =IF(AD32="Availability", 0, IF(AND(AE32="Y", OR(J32>2, L32>0)), 1, 0)) -> 0 | AJ32: 701A | AK32: 2BD | AL32: =IFERROR(IF(AK32="", "", _xlfn.XLOOKUP(AK32, CODES!A:A,CODES!E:E)), "") -> LNER | AM32: =IFERROR(IF(AK32="", "", _xlfn.XLOOKUP(AK32, CODES!A:A,CODES!G:G)), "") -> Other | AN32: =IFERROR(IF(AK32="", "", _xlfn.XLOOKUP(AK32, CODES!A:A,CODES!I:I)), "") -> Availability | AO32: Unit 801220 not available for service due to the ongoing investigation into reports of a mouse in vehicle 824220 reported whilst working as 1S25 on the 05/02.
A33: Root Cause | B33: 2612 | C33: 177582 | D33: 46059 | E33: 5Y23 | F33: 21:22 KINGS X to BOUNDGNCS | G33: FERMEPK | H33: 44 | I33: 0 | J33: 44 | K33: 44 | L33: 0 | M33: 801108/01 | O33: 801108 | P33: 801101 | Q33: 5 | R33: 80x | S33: 43700 | T33: 5Y23 DEPOT OPS FERMEPK 05/02 DEPOT OPS FEREM PARK | U33: HRE Reject, MTIN – No. Waiting acceptance onto Bounds Green. Depot report 5Y23 was 45 minutes late off the wash road due to 5Y86 being processed ahead and then waiting for a road onto the Depot. Class 5 only delay. | W33: MHBJ | X33: MHBJ | Y33: MU | Z33: MU | AA33: A | AB33: Accepted | AC33: Accepted | AE33: 260206-177582 | AG33: Rejected - Class 3/5 | AH33: N | AI33: =IF(AD33="Availability", 0, IF(AND(AE33="Y", OR(J33>2, L33>0)), 1, 0)) -> 0 | AJ33: 701A | AK33: 1BD | AL33: =IFERROR(IF(AK33="", "", _xlfn.XLOOKUP(AK33, CODES!A:A,CODES!E:E)), "") -> Operational | AM33: =IFERROR(IF(AK33="", "", _xlfn.XLOOKUP(AK33, CODES!A:A,CODES!G:G)), "") -> Depot | AN33: =IFERROR(IF(AK33="", "", _xlfn.XLOOKUP(AK33, CODES!A:A,CODES!I:I)), "") -> Process | AO33: Unit late onto depot.
A34: Root Cause | B34: 2612 | C34: 176963 | D34: 46058 | E34: 1E25 | F34: 14:52 ABERDEEN to KINGS X | G34: KDY INK | H34: 2 | I34: 0 | J34: 2 | K34: 2 | L34: 0 | M34: 800105 | O34: 800105 | Q34: 9 | R34: 80x | S34: 43572 | T34: 1E25 2 LOST KDY INK Adhesion. | U34: Sub threshold delay. | W34: MHB1 | X34: MHB1 | Y34: MP | AA34: A | AB34: New | AC34: Accepted | AE34: 260205-176963 | AG34: Rejected - Sub Threshold | AH34: N | AI34: =IF(AD34="Availability", 0, IF(AND(AE34="Y", OR(J34>2, L34>0)), 1, 0)) -> 0 | AJ34: 750 | AK34: 2BE | AL34: =IFERROR(IF(AK34="", "", _xlfn.XLOOKUP(AK34, CODES!A:A,CODES!E:E)), "") -> LNER | AM34: =IFERROR(IF(AK34="", "", _xlfn.XLOOKUP(AK34, CODES!A:A,CODES!G:G)), "") -> Other | AN34: =IFERROR(IF(AK34="", "", _xlfn.XLOOKUP(AK34, CODES!A:A,CODES!I:I)), "") -> Adhesion | AO34: Adhesion.
A35: Removed - Reassigned | B35: 2612 | C35: 176917 | D35: 46058 | E35: 1S24 | F35: 16:30 KINGS X to EDINBURGH | G35: YRK | H35: 3 | I35: 0 | J35: 3 | K35: 3 | L35: 0 | M35: 801209 | N35: 829209 | O35: 801209 | Q35: 9 | R35: 80x | S35: 43791 | T35: 1S24 3 OVERTIME YRK Door B in Coach M has LOOU. LOG 260205-75 refers. SAP 8331983 refers - Door B LOOU. | U35: Further details required please. Quartz states Customer in a wheelchair needing to board the service, door in M out of use and couldn’t use door in L as expected. Had to board customer in A instead and bring the lady to the front of the train from the rear. No active door faults raised in SAP or recorded in the HMC Log. MTIN NO, HRE REJECT - As discussed, a route message was sent out at 13:53 advising that Door B of 829209 was LOOU. It appears that this was not managed correctly in service resulting in an avoidable delay at York. | V35: Door appears to have been LOOU on 3S02 leaving leeds. Awaiting TM report from AAB. JM has provided details on it. JC 06/02 AAB has reported back. Details sent onto CPT. JC 12/02 referral request sent to LJ at York. JC 12/02 | W35: RHBK | X35: RHBK | Y35: RC | AA35: A | AB35: New | AC35: Referred | AE35: 260205-176917 | AG35: Rejected | AH35: N | AI35: =IF(AD35="Availability", 0, IF(AND(AE35="Y", OR(J35>2, L35>0)), 1, 0)) -> 0 | AJ35: 701E | AK35: 1AD | AL35: =IFERROR(IF(AK35="", "", _xlfn.XLOOKUP(AK35, CODES!A:A,CODES!E:E)), "") -> Operational | AM35: =IFERROR(IF(AK35="", "", _xlfn.XLOOKUP(AK35, CODES!A:A,CODES!G:G)), "") -> Staff | AN35: =IFERROR(IF(AK35="", "", _xlfn.XLOOKUP(AK35, CODES!A:A,CODES!I:I)), "") -> Platform | AO35: Route message not adhered to.
A36: Root Cause | B36: 2612 | C36: 176008 | D36: 46058 | E36: 1S05 | F36: 07:03 KINGS X to EDINBURGH | G36: BELFORD BWK | H36: 4 | I36: 0 | J36: 4 | K36: 11 | L36: 0 | M36: 801218 | N36: 825218 | O36: 801218 | Q36: 9 | R36: 80x | S36: 43998 | T36: 1S05 4 LOST BELFORD BWK TMS 4045 VCB2(3) Close Failure SAP 8337507 refers. | U36: Under investigation. | W36: MHB2 | X36: MHB2 | Y36: MD | AA36: A | AB36: New | AC36: Investigation | AE36: 260205-176008 | AG36: Investigation | AI36: =IF(AD36="Availability", 0, IF(AND(AE36="Y", OR(J36>2, L36>0)), 1, 0)) -> 0 | AJ36: 701D | AL36: =IFERROR(IF(AK36="", "", _xlfn.XLOOKUP(AK36, CODES!A:A,CODES!E:E)), "") | AM36: =IFERROR(IF(AK36="", "", _xlfn.XLOOKUP(AK36, CODES!A:A,CODES!G:G)), "") | AN36: =IFERROR(IF(AK36="", "", _xlfn.XLOOKUP(AK36, CODES!A:A,CODES!I:I)), "")
A37: Root Cause | B37: 2612 | C37: 175515 | D37: 46058 | E37: 1S04 | F37: 06:30 KINGS X to EDINBURG | G37: NNG RET | H37: 6 | I37: 0 | J37: 6 | K37: 6 | L37: 0 | M37: 801207 | N37: 825207 | O37: 801207 | Q37: 9 | R37: 80x | S37: 43783 | T37: 1S04 3 LOST NNG RET TMS 0637 Door B Open while Running. LOG 260205-56 refers. SAP 8337306 refers - slight adjustment carried out to DCS. | U37: MTIN YES, HRE ACCEPT - DCS (old type) to be replaced. | W37: MHB2 | X37: MHB2 | Y37: M7 | Z37: M7 | AA37: A | AB37: Accepted | AC37: Accepted | AE37: 260205-175515 | AG37: Accepted | AH37: Y | AI37: =IF(AD37="Availability", 0, IF(AND(AE37="Y", OR(J37>2, L37>0)), 1, 0)) -> 0 | AJ37: 701D | AK37: OBD | AL37: =IFERROR(IF(AK37="", "", _xlfn.XLOOKUP(AK37, CODES!A:A,CODES!E:E)), "") -> Doors | AM37: =IFERROR(IF(AK37="", "", _xlfn.XLOOKUP(AK37, CODES!A:A,CODES!G:G)), "") -> Exterior Passenger Doors | AN37: =IFERROR(IF(AK37="", "", _xlfn.XLOOKUP(AK37, CODES!A:A,CODES!I:I)), "") -> Door Close Switch (DCS) | AO37: TMS 0637 Door B Open while Running, old DCS to be replaced.
A38: Check - not on Fleet Attr | B38: 2612 | C38: 175190 | D38: 46058 | F38: 05:35 Neville Hill T&R.S.M.D - Leeds | G38: XNL | J38: 4 | K38: 4 | L38: 0 | M38: NL12 | O38: NL12 | Q38: 11 | R38: 225 | T38: 5A05 4 LATE START XNL | U38: Waiting signals | W38: MHBM | X38: MHBM | Y38: MU | AA38: D | AB38: New | AC38: Investigation | AE38: 260205-175190 | AH38: N | AI38: =IF(AD38="Availability", 0, IF(AND(AE38="Y", OR(J38>2, L38>0)), 1, 0)) -> 0 | AJ38: 701A | AL38: =IFERROR(IF(AK38="", "", _xlfn.XLOOKUP(AK38, CODES!A:A,CODES!E:E)), "") | AM38: =IFERROR(IF(AK38="", "", _xlfn.XLOOKUP(AK38, CODES!A:A,CODES!G:G)), "") | AN38: =IFERROR(IF(AK38="", "", _xlfn.XLOOKUP(AK38, CODES!A:A,CODES!I:I)), "")
A39: Root Cause | B39: 2612 | C39: 173841 | D39: 46057 | E39: 1A24 | F39: 14:40 Leeds - London Kings Cross | G39: AWK DON | J39: 14 | K39: 23 | L39: 0 | M39: NL26 | N39: 91110 | O39: NL26 | Q39: 11 | R39: 225 | T39: 1A24 3 LOST AWK DON | U39: General fault light lit | V39: WO 5088912 MPU shows No1 bogie overload | W39: MHBA | X39: MHBA | Y39: M1 | Z39: M1 | AA39: A | AB39: Accepted | AC39: Accepted | AE39: 260204-173841 | AH39: Y | AI39: =IF(AD39="Availability", 0, IF(AND(AE39="Y", OR(J39>2, L39>0)), 1, 0)) -> 0 | AJ39: 701D | AL39: =IFERROR(IF(AK39="", "", _xlfn.XLOOKUP(AK39, CODES!A:A,CODES!E:E)), "") | AM39: =IFERROR(IF(AK39="", "", _xlfn.XLOOKUP(AK39, CODES!A:A,CODES!G:G)), "") | AN39: =IFERROR(IF(AK39="", "", _xlfn.XLOOKUP(AK39, CODES!A:A,CODES!I:I)), "")
A40: Root Cause | B40: 2612 | C40: 172843 | D40: 46057 | E40: 3A13 | F40: 07:12 NEVHILL D to HARROGATE | G40: XNL | H40: 11 | I40: 0 | J40: 11 | K40: 11 | L40: 0 | M40: 800101 | O40: 800101 | Q40: 9 | R40: 80x | S40: 43920 | T40: 3A13 11 LATE START XNL DEPOT REPORT DELAYED FOLLOWING LATE 3Y06. AS ON DEPOT, EACH OPERATOR TAKES OWN DELAY. | U40: HRE Reject, MTIN – No. Depot report 3A13 delayed following late departing 3Y06, which was delayed due to the Driver arriving late. Class 3 only delay. | W40: MHBM | X40: MHBM | Y40: MU | AA40: A | AB40: New | AC40: Accepted | AE40: 260204-172843 | AG40: Rejected - Class 3/5 | AH40: N | AI40: =IF(AD40="Availability", 0, IF(AND(AE40="Y", OR(J40>2, L40>0)), 1, 0)) -> 0 | AJ40: 701A | AK40: 1BD | AL40: =IFERROR(IF(AK40="", "", _xlfn.XLOOKUP(AK40, CODES!A:A,CODES!E:E)), "") -> Operational | AM40: =IFERROR(IF(AK40="", "", _xlfn.XLOOKUP(AK40, CODES!A:A,CODES!G:G)), "") -> Depot | AN40: =IFERROR(IF(AK40="", "", _xlfn.XLOOKUP(AK40, CODES!A:A,CODES!I:I)), "") -> Process | AO40: Unit late off depot.
...

Sheet LOOKUPS
A1: LNER_Fleet_Status | B1: Who_Accepted | C1: Who_Referred | D1: Who_Requested | E1: Waiting_Att_Mgr_Decision | F1: Wtg_Referral_Dec | G1: Hitachi_Status | H1: Yes_No | I1: Vehicle_No | J1: Unit_No
A2: Investigation | B2: Fleet | C2: 225 Fleet Tech | D2: Driver | E2: Driver Error | F2: 225 Fleet Tech | G2: Investigation | H2: Y | I2: 811101 | J2: 800101
A3: Accepted | B3: Other | C3: TM | D3: TM | E3: TM Error | F3: TM | G3: Accepted | H3: N | I3: 811102 | J3: 800102
A4: Referred | B4: 225 Depot | C4: Driver | D4: Station | E4: Driver Door Obstacle | F4: Driver | G4: Availability | I4: 811103 | J4: 800103
A5: Report_Requested | C5: Station | D5: Onboard | E5: Passengers | F5: Station | G5: Merged | I5: 811104 | J5: 800104
A6: Merged with Master | C6: NR | D6: HRL | E6: Incorrect Dispatch | F6: NR | G6: TOC Dispute | I6: 811105 | J6: 800105
A7: Refer to Level 2 | C7: Control | D7: Ops | E7: Incident not Reported to MC | F7: Control | G7: Rejected - Class 3/5 | I7: 811106 | J7: 800106
A8: Wtg_Att_Mgr_Dec | C8: Other | D8: NR | E8: Awaiting Stoke Tech | F8: Other | G8: Rejected - Unsold Unit | I8: 811107 | J8: 800107
A9: Wtg_Referral_Dec | C9: Vandalism | E9: Awaiting CCF to Review | F9: Vandalism | G9: Rejected - Sub Threshold | I9: 811108 | J9: 800108
A10: Discuss with HRL | E10: Awaiting NR | F10: Awaiting DRV Report | G10: Rejected - 225 delay | I10: 811109 | J10: 800109
E11: Awaiting Amendment TRUST/Bugle Code | F11: Awaiting DTM to Review | G11: Rejected | I11: 811110 | J11: 800110
E12: Awaiting Attribution Decision | F12: Awaiting TM Report | I12: 811111 | J12: 800111
F13: Awaiting Referral Acceptance | I13: 811112 | J13: 800112
I14: 811113 | J14: 800113
I15: 812101 | J15: 800201
I16: 812102 | J16: 800202
I17: 812103 | J17: 800203
I18: 812104 | J18: 800204
I19: 812105 | J19: 800205
I20: 812106 | J20: 800206
I21: 812107 | J21: 800207
I22: 812108 | J22: 800208
I23: 812109 | J23: 800209
I24: 812110 | J24: 800210
I25: 812111 | J25: 801101
... I75: 816109 | J75: undefined
I76: 816110
I77: 816111
I78: 816112
I79: 816113
I80: 817101
I81: 817102
I82: 817103
I83: 817104
I84: 817105
I85: 817106
I86: 817107
I87: 817108
... I592: 91130

Sheet CODES
A1: Code | B1: System_SubSystem_Component | C1: Safety_Critical | D1: System_Code | E1: System | F1: SubSystem_Code | G1: SubSystem | H1: Component_Code | I1: Component | J1: Fleet
A2: 1A9 | B2: Operational_Staff_No Fault Identified | C2: N | D2: 1 | E2: Operational | F2: A | G2: Staff | H2: 9 | I2: No Fault Identified | J2: Azuma
A3: 1AA | B3: Operational_Staff_Driver | C3: N | D3: 1 | E3: Operational | F3: A | G3: Staff | H3: A | I3: Driver | J3: Azuma
A4: 1AB | B4: Operational_Staff_TM | C4: N | D4: 1 | E4: Operational | F4: A | G4: Staff | H4: B | I4: TM | J4: Azuma
A5: 1AC | B5: Operational_Staff_Train Crew | C5: N | D5: 1 | E5: Operational | F5: A | G5: Staff | H5: C | I5: Train Crew | J5: Azuma
A6: 1AD | B6: Operational_Staff_Platform | C6: N | D6: 1 | E6: Operational | F6: A | G6: Staff | H6: D | I6: Platform | J6: Azuma
A7: 1AE | B7: Operational_Staff_Other | C7: N | D7: 1 | E7: Operational | F7: A | G7: Staff | H7: E | I7: Other | J7: Azuma
A8: 1B9 | B8: Operational_Depot_No Fault Identified | C8: N | D8: 1 | E8: Operational | F8: B | G8: Depot | H8: 9 | I8: No Fault Identified | J8: Azuma
A9: 1BA | B9: Operational_Depot_InfraStructure | C9: N | D9: 1 | E9: Operational | F9: B | G9: Depot | H9: A | I9: InfraStructure | J9: Azuma
A10: 1BB | B10: Operational_Depot_Awaiting Acceptance | C10: N | D10: 1 | E10: Operational | F10: B | G10: Depot | H10: B | I10: Awaiting Acceptance | J10: Azuma
A11: 1BC | B11: Operational_Depot_Planning | C11: N | D11: 1 | E11: Operational | F11: B | G11: Depot | H11: C | I11: Planning | J11: Azuma
A12: 1BD | B12: Operational_Depot_Process | C12: N | D12: 1 | E12: Operational | F12: B | G12: Depot | H12: D | I12: Process | J12: Azuma
... A88: 225-2BN | B88: LNER_Other_Passenger Vandalism | C88: N | D88: 2 | E88: LNER | F88: B | G88: Other | H88: N | I88: Passenger Vandalism | J88: 225
A89: 225-AA1 | B89: Air System_Control_No Fault Identified | D89: A | E89: Air System | F89: A | G89: Control | H89: 1 | I89: No Fault Identified | J89: 225
A90: 225-AAA | B90: Air System_Control_Contactor Single phase | D90: A | E90: Air System | F90: A | G90: Control | H90: A | I90: Contactor Single phase | J90: 225
A91: 225-AAB | B91: Air System_Control_Contactor three phase | D91: A | E91: Air System | F91: A | G91: Control | H91: B | I91: Contactor three phase | J91: 225
A92: 225-AAC | B92: Air System_Control_Contactor - Change over | D92: A | E92: Air System | F92: A | G92: Control | H92: C | I92: Contactor - Change over | J92: 225
A93: 225-AAD | B93: Air System_Control_Contactor coil | D93: A | E93: Air System | F93: A | G93: Control | H93: D | I93: Contactor coil | J93: 225
A94: 225-AAE | B94: Air System_Control_Contactor fixed tip | D94: A | E94: Air System | F94: A | G94: Control | H94: E | I94: Contactor fixed tip | J94: 225
A95: 225-AAF | B95: Air System_Control_Contactor moving tip | D95: A | E95: Air System | F95: A | G95: Control | H95: F | I95: Contactor moving tip | J95: 225
A96: 225-AAG | B96: Air System_Control_Knuckle Spring | D96: A | E96: Air System | F96: A | G96: Control | H96: G | I96: Knuckle Spring | J96: 225
A97: 225-AAH | B97: Air System_Control_Terminal Connections | D97: A | E97: Air System | F97: A | G97: Control | H97: H | I97: Terminal Connections | J97: 225
A98: 225-AAI | B98: Air System_Control_Terminal fasteners | D98: A | E98: Air System | F98: A | G98: Control | H98: I | I98: Terminal fasteners | J98: 225
A99: 225-AAJ | B99: Air System_Control_Arc Chute | D99: A | E99: Air System | F99: A | G99: Control | H99: J | I99: Arc Chute | J99: 225
A100: 225-AAK | B100: Air System_Control_Wiring | D100: A | E100: Air System | F100: A | G100: Control | H100: K | I100: Wiring | J100: 225
... A2753: 225-ZFH | B2753: Equipment_Portable Fire_Fire Blanket (catering) | D2753: Z | E2753: Equipment | F2753: F | G2753: Portable Fire | H2753: H | I2753: Fire Blanket (catering) | J2753: 225
A2754: AA6 | B2754: Air System_Air Horn_Fault not Investigated | C2754: Y | D2754: A | E2754: Air System | F2754: A | G2754: Air Horn | H2754: 6 | I2754: Fault not Investigated | J2754: Azuma
A2755: AA7 | B2755: Air System_Air Horn_Non Technical | C2755: Y | D2755: A | E2755: Air System | F2755: A | G2755: Air Horn | H2755: 7 | I2755: Non Technical | J2755: Azuma
A2756: AA8 | B2756: Air System_Air Horn_Operator | C2756: Y | D2756: A | E2756: Air System | F2756: A | G2756: Air Horn | H2756: 8 | I2756: Operator | J2756: Azuma
A2757: AA9 | B2757: Air System_Air Horn_No Fault Identified | C2757: Y | D2757: A | E2757: Air System | F2757: A | G2757: Air Horn | H2757: 9 | I2757: No Fault Identified | J2757: Azuma
A2758: AAA | B2758: Air System_Air Horn_EP Valve | C2758: Y | D2758: A | E2758: Air System | F2758: A | G2758: Air Horn | H2758: A | I2758: EP Valve | J2758: Azuma
A2759: AAB | B2759: Air System_Air Horn_Horn | C2759: Y | D2759: A | E2759: Air System | F2759: A | G2759: Air Horn | H2759: B | I2759: Horn | J2759: Azuma
A2760: AAC | B2760: Air System_Air Horn_Horn Pressure Switch | C2760: Y | D2760: A | E2760: Air System | F2760: A | G2760: Air Horn | H2760: C | I2760: Horn Pressure Switch | J2760: Azuma
A2761: AAD | B2761: Air System_Air Horn_Lever Operated Horn Valve | C2761: Y | D2761: A | E2761: Air System | F2761: A | G2761: Air Horn | H2761: D | I2761: Lever Operated Horn Valve | J2761: Azuma
A2762: AAE | B2762: Air System_Air Horn_Pipework | C2762: Y | D2762: A | E2762: Air System | F2762: A | G2762: Air Horn | H2762: E | I2762: Pipework | J2762: Azuma
A2763: AAF | B2763: Air System_Air Horn_Regulator | C2763: Y | D2763: A | E2763: Air System | F2763: A | G2763: Air Horn | H2763: F | I2763: Regulator | J2763: Azuma
A2764: AAG | B2764: Air System_Air Horn_Thermostatic Junction Box | C2764: Y | D2764: A | E2764: Air System | F2764: A | G2764: Air Horn | H2764: G | I2764: Thermostatic Junction Box | J2764: Azuma
A2765: AAH | B2765: Air System_Air Horn_Adverse Weather | C2765: Y | D2765: A | E2765: Air System | F2765: A | G2765: Air Horn | H2765: H | I2765: Adverse Weather | J2765: Azuma
... A2870: BCC | B2870: Brake System_Cab & Vestibule Equipment_Brake Coding MCB | C2870: Y | D2870: B | E2870: Brake System | F2870: C | G2870: Cab & Vestibule Equipment | H2870: C | I2870: Brake Coding MCB | J2870: Azuma
A2871: C8 | B2871: Water and Toilet Systems_SST Toilet Door_Operator | C2871: N | E2871: Water and Toilet Systems | F2871: C | G2871: SST Toilet Door | H2871: 8 | I2871: Operator | J2871: Azuma
...
